<?xml version="1.0" ?>
<!-- =================================================================================== -->
<!-- |    This document was autogenerated by xacro from aprs_lab_robots.urdf.xacro     | -->
<!-- |    EDITING THIS FILE BY HAND IS NOT RECOMMENDED                                 | -->
<!-- =================================================================================== -->
<robot name="aprs_lab_robots">
  <link name="world"/>
  <link name="aprs_ur_base_link"/>
  <link name="aprs_fanuc_base_link"/>
  <link name="aprs_motoman_base_link"/>
  <joint name="ur_world_to_base" type="fixed">
    <origin rpy="0 0 0" xyz="10 0 0"/>
    <parent link="world"/>
    <child link="aprs_ur_base_link"/>
  </joint>
  <joint name="fanuc_world_to_base" type="fixed">
    <origin rpy="0 0 0" xyz="0 10 0"/>
    <parent link="world"/>
    <child link="aprs_fanuc_base_link"/>
  </joint>
  <joint name="franka_world_to_base" type="fixed">
    <origin rpy="0 0 0" xyz="0 0 0"/>
    <parent link="world"/>
    <child link="aprs_franka_base_link"/>
  </joint>
  <joint name="motoman_world_to_base" type="fixed">
    <origin rpy="0 0 0" xyz="10 10 0"/>
    <parent link="world"/>
    <child link="aprs_motoman_base_link"/>
  </joint>
  <!--
    Base UR robot series xacro macro.

    NOTE this is NOT a URDF. It cannot directly be loaded by consumers
    expecting a flattened '.urdf' file. See the top-level '.xacro' for that
    (but note that .xacro must still be processed by the xacro command).

    This file models the base kinematic chain of a UR robot, which then gets
    parameterised by various configuration files to convert it into a UR3(e),
    UR5(e), UR10(e) or UR16e.

    NOTE the default kinematic parameters (i.e., link lengths, frame locations,
    offsets, etc) do not correspond to any particular robot. They are defaults
    only. There WILL be non-zero offsets between the Forward Kinematics results
    in TF (i.e., robot_state_publisher) and the values reported by the Teach
    Pendant.

    For accurate (and robot-specific) transforms, the 'kinematics_parameters_file'
    parameter MUST point to a .yaml file containing the appropriate values for
    the targeted robot.

    If using the UniversalRobots/Universal_Robots_ROS_Driver, follow the steps
    described in the readme of that repository to extract the kinematic
    calibration from the controller and generate the required .yaml file.

    Main author of the migration to yaml configs Ludovic Delval.

    Contributors to previous versions (in no particular order)

     - Denis Stogl
     - Lovro Ivanov
     - Felix Messmer
     - Kelsey Hawkins
     - Wim Meeussen
     - Shaun Edwards
     - Nadia Hammoudeh Garcia
     - Dave Hershberger
     - G. vd. Hoorn
     - Philip Long
     - Dave Coleman
     - Miguel Prada
     - Mathias Luedtke
     - Marcel Schnirring
     - Felix von Drigalski
     - Felix Exner
     - Jimmy Da Silva
     - Ajit Krisshna N L
     - Muhammad Asif Rana
  -->
  <!-- links -  main serial chain -->
  <link name="base_link"/>
  <link name="base_link_inertia">
    <visual>
      <origin rpy="0 0 3.141592653589793" xyz="0 0 0"/>
      <geometry>
        <mesh filename="package://ur_description/meshes/ur10e/visual/base.dae"/>
      </geometry>
    </visual>
    <collision>
      <origin rpy="0 0 3.141592653589793" xyz="0 0 0"/>
      <geometry>
        <mesh filename="package://ur_description/meshes/ur10e/collision/base.stl"/>
      </geometry>
    </collision>
    <inertial>
      <mass value="4.0"/>
      <origin rpy="0 0 0" xyz="0 0 0"/>
      <inertia ixx="0.0061063308908" ixy="0.0" ixz="0.0" iyy="0.0061063308908" iyz="0.0" izz="0.01125"/>
    </inertial>
  </link>
  <link name="shoulder_link">
    <visual>
      <origin rpy="0 0 3.141592653589793" xyz="0 0 0"/>
      <geometry>
        <mesh filename="package://ur_description/meshes/ur10e/visual/shoulder.dae"/>
      </geometry>
    </visual>
    <collision>
      <origin rpy="0 0 3.141592653589793" xyz="0 0 0"/>
      <geometry>
        <mesh filename="package://ur_description/meshes/ur10e/collision/shoulder.stl"/>
      </geometry>
    </collision>
    <inertial>
      <mass value="7.778"/>
      <origin rpy="0 0 0" xyz="0 0 0"/>
      <inertia ixx="0.03147431257693659" ixy="0.0" ixz="0.0" iyy="0.03147431257693659" iyz="0.0" izz="0.021875624999999996"/>
    </inertial>
  </link>
  <link name="upper_arm_link">
    <visual>
      <origin rpy="1.5707963267948966 0 -1.5707963267948966" xyz="0 0 0.1762"/>
      <geometry>
        <mesh filename="package://ur_description/meshes/ur10e/visual/upperarm.dae"/>
      </geometry>
    </visual>
    <collision>
      <origin rpy="1.5707963267948966 0 -1.5707963267948966" xyz="0 0 0.1762"/>
      <geometry>
        <mesh filename="package://ur_description/meshes/ur10e/collision/upperarm.stl"/>
      </geometry>
    </collision>
    <inertial>
      <mass value="12.93"/>
      <origin rpy="0 1.5707963267948966 0" xyz="-0.306 0.0 0.175"/>
      <inertia ixx="0.42175380379841093" ixy="0.0" ixz="0.0" iyy="0.42175380379841093" iyz="0.0" izz="0.03636562499999999"/>
    </inertial>
  </link>
  <link name="forearm_link">
    <visual>
      <origin rpy="1.5707963267948966 0 -1.5707963267948966" xyz="0 0 0.0393"/>
      <geometry>
        <mesh filename="package://ur_description/meshes/ur10e/visual/forearm.dae"/>
      </geometry>
    </visual>
    <collision>
      <origin rpy="1.5707963267948966 0 -1.5707963267948966" xyz="0 0 0.0393"/>
      <geometry>
        <mesh filename="package://ur_description/meshes/ur10e/collision/forearm.stl"/>
      </geometry>
    </collision>
    <inertial>
      <mass value="3.87"/>
      <origin rpy="0 1.5707963267948966 0" xyz="-0.285775 0.0 0.0393"/>
      <inertia ixx="0.11079302548902206" ixy="0.0" ixz="0.0" iyy="0.11079302548902206" iyz="0.0" izz="0.010884375"/>
    </inertial>
  </link>
  <link name="wrist_1_link">
    <visual>
      <origin rpy="1.5707963267948966 0 0" xyz="0 0 -0.135"/>
      <geometry>
        <mesh filename="package://ur_description/meshes/ur10e/visual/wrist1.dae"/>
      </geometry>
    </visual>
    <collision>
      <origin rpy="1.5707963267948966 0 0" xyz="0 0 -0.135"/>
      <geometry>
        <mesh filename="package://ur_description/meshes/ur10e/collision/wrist1.stl"/>
      </geometry>
    </collision>
    <inertial>
      <mass value="1.96"/>
      <origin rpy="0 0 0" xyz="0 0 0"/>
      <inertia ixx="0.005108247956699999" ixy="0.0" ixz="0.0" iyy="0.005108247956699999" iyz="0.0" izz="0.005512499999999999"/>
    </inertial>
  </link>
  <link name="wrist_2_link">
    <visual>
      <origin rpy="0 0 0" xyz="0 0 -0.12"/>
      <geometry>
        <mesh filename="package://ur_description/meshes/ur10e/visual/wrist2.dae"/>
      </geometry>
    </visual>
    <collision>
      <origin rpy="0 0 0" xyz="0 0 -0.12"/>
      <geometry>
        <mesh filename="package://ur_description/meshes/ur10e/collision/wrist2.stl"/>
      </geometry>
    </collision>
    <inertial>
      <mass value="1.96"/>
      <origin rpy="0 0 0" xyz="0 0 0"/>
      <inertia ixx="0.005108247956699999" ixy="0.0" ixz="0.0" iyy="0.005108247956699999" iyz="0.0" izz="0.005512499999999999"/>
    </inertial>
  </link>
  <link name="wrist_3_link">
    <visual>
      <origin rpy="1.5707963267948966 0 0" xyz="0 0 -0.1168"/>
      <geometry>
        <mesh filename="package://ur_description/meshes/ur10e/visual/wrist3.dae"/>
      </geometry>
    </visual>
    <collision>
      <origin rpy="1.5707963267948966 0 0" xyz="0 0 -0.1168"/>
      <geometry>
        <mesh filename="package://ur_description/meshes/ur10e/collision/wrist3.stl"/>
      </geometry>
    </collision>
    <inertial>
      <mass value="0.202"/>
      <origin rpy="0 0 0" xyz="0.0 0.0 -0.025"/>
      <inertia ixx="0.00014434577559500002" ixy="0.0" ixz="0.0" iyy="0.00014434577559500002" iyz="0.0" izz="0.00020452500000000002"/>
    </inertial>
  </link>
  <!-- base_joint fixes base_link to the environment -->
  <joint name="base_joint" type="fixed">
    <origin rpy="0 0 0" xyz="0 0 0.05"/>
    <parent link="aprs_ur_base_link"/>
    <child link="base_link"/>
  </joint>
  <!-- joints - main serial chain -->
  <joint name="base_link-base_link_inertia" type="fixed">
    <parent link="base_link"/>
    <child link="base_link_inertia"/>
    <!-- 'base_link' is REP-103 aligned (so X+ forward), while the internal
           frames of the robot/controller have X+ pointing backwards.
           Use the joint between 'base_link' and 'base_link_inertia' (a dummy
           link/frame) to introduce the necessary rotation over Z (of pi rad).
      -->
    <origin rpy="0 0 3.141592653589793" xyz="0 0 0"/>
  </joint>
  <joint name="shoulder_pan_joint" type="revolute">
    <parent link="base_link_inertia"/>
    <child link="shoulder_link"/>
    <origin rpy="0 0 0" xyz="0 0 0.1807"/>
    <axis xyz="0 0 1"/>
    <limit effort="330.0" lower="-6.283185307179586" upper="6.283185307179586" velocity="2.0943951023931953"/>
    <dynamics damping="0" friction="0"/>
  </joint>
  <joint name="shoulder_lift_joint" type="revolute">
    <parent link="shoulder_link"/>
    <child link="upper_arm_link"/>
    <origin rpy="1.570796327 0 0" xyz="0 0 0"/>
    <axis xyz="0 0 1"/>
    <limit effort="330.0" lower="-6.283185307179586" upper="6.283185307179586" velocity="2.0943951023931953"/>
    <dynamics damping="0" friction="0"/>
  </joint>
  <joint name="elbow_joint" type="revolute">
    <parent link="upper_arm_link"/>
    <child link="forearm_link"/>
    <origin rpy="0 0 0" xyz="-0.6127 0 0"/>
    <axis xyz="0 0 1"/>
    <limit effort="150.0" lower="-3.141592653589793" upper="3.141592653589793" velocity="3.141592653589793"/>
    <dynamics damping="0" friction="0"/>
  </joint>
  <joint name="wrist_1_joint" type="revolute">
    <parent link="forearm_link"/>
    <child link="wrist_1_link"/>
    <origin rpy="0 0 0" xyz="-0.57155 0 0.17415"/>
    <axis xyz="0 0 1"/>
    <limit effort="56.0" lower="-6.283185307179586" upper="6.283185307179586" velocity="3.141592653589793"/>
    <dynamics damping="0" friction="0"/>
  </joint>
  <joint name="wrist_2_joint" type="revolute">
    <parent link="wrist_1_link"/>
    <child link="wrist_2_link"/>
    <origin rpy="1.570796327 0 0" xyz="0 -0.11985 -2.458164590756244e-11"/>
    <axis xyz="0 0 1"/>
    <limit effort="56.0" lower="-6.283185307179586" upper="6.283185307179586" velocity="3.141592653589793"/>
    <dynamics damping="0" friction="0"/>
  </joint>
  <joint name="wrist_3_joint" type="revolute">
    <parent link="wrist_2_link"/>
    <child link="wrist_3_link"/>
    <origin rpy="1.570796326589793 3.141592653589793 3.141592653589793" xyz="0 0.11655 -2.390480459346185e-11"/>
    <axis xyz="0 0 1"/>
    <limit effort="56.0" lower="-6.283185307179586" upper="6.283185307179586" velocity="3.141592653589793"/>
    <dynamics damping="0" friction="0"/>
  </joint>
  <link name="ft_frame"/>
  <joint name="wrist_3_link-ft_frame" type="fixed">
    <parent link="wrist_3_link"/>
    <child link="ft_frame"/>
    <origin rpy="3.141592653589793 0 0" xyz="0 0 0"/>
  </joint>
  <!-- ROS-Industrial 'base' frame - base_link to UR 'Base' Coordinates transform -->
  <link name="base"/>
  <joint name="base_link-base_fixed_joint" type="fixed">
    <!-- Note the rotation over Z of pi radians - as base_link is REP-103
           aligned (i.e., has X+ forward, Y+ left and Z+ up), this is needed
           to correctly align 'base' with the 'Base' coordinate system of
           the UR controller.
      -->
    <origin rpy="0 0 3.141592653589793" xyz="0 0 0"/>
    <parent link="base_link"/>
    <child link="base"/>
  </joint>
  <!-- ROS-Industrial 'flange' frame - attachment point for EEF models -->
  <link name="flange"/>
  <joint name="wrist_3-flange" type="fixed">
    <parent link="wrist_3_link"/>
    <child link="flange"/>
    <origin rpy="0 -1.5707963267948966 -1.5707963267948966" xyz="0 0 0"/>
  </joint>
  <!-- ROS-Industrial 'tool0' frame - all-zeros tool frame -->
  <link name="tool0"/>
  <joint name="flange-tool0" type="fixed">
    <!-- default toolframe - X+ left, Y+ up, Z+ front -->
    <origin rpy="1.5707963267948966 0 1.5707963267948966" xyz="0 0 0"/>
    <parent link="flange"/>
    <child link="tool0"/>
  </joint>
  <ros2_control name="ur" type="system">
    <hardware>
      <plugin>gz_ros2_control/GazeboSimSystem</plugin>
    </hardware>
    <joint name="shoulder_pan_joint">
      <command_interface name="position">
        <param name="min">{-2*pi}</param>
        <param name="max">{2*pi}</param>
      </command_interface>
      <state_interface name="position">
        <!-- initial position for the FakeSystem and simulation -->
        <param name="initial_value">0.0</param>
      </state_interface>
      <state_interface name="velocity"/>
      <state_interface name="effort"/>
    </joint>
    <joint name="shoulder_lift_joint">
      <command_interface name="position">
        <param name="min">{-2*pi}</param>
        <param name="max">{2*pi}</param>
      </command_interface>
      <state_interface name="position">
        <!-- initial position for the FakeSystem and simulation -->
        <param name="initial_value">-1.57</param>
      </state_interface>
      <state_interface name="velocity"/>
      <state_interface name="effort"/>
    </joint>
    <joint name="elbow_joint">
      <command_interface name="position">
        <param name="min">{-pi}</param>
        <param name="max">{pi}</param>
      </command_interface>
      <state_interface name="position">
        <!-- initial position for the FakeSystem and simulation -->
        <param name="initial_value">1.57</param>
      </state_interface>
      <state_interface name="velocity"/>
      <state_interface name="effort"/>
    </joint>
    <joint name="wrist_1_joint">
      <command_interface name="position">
        <param name="min">{-2*pi}</param>
        <param name="max">{2*pi}</param>
      </command_interface>
      <state_interface name="position">
        <!-- initial position for the FakeSystem and simulation -->
        <param name="initial_value">-1.571</param>
      </state_interface>
      <state_interface name="velocity"/>
      <state_interface name="effort"/>
    </joint>
    <joint name="wrist_2_joint">
      <command_interface name="position">
        <param name="min">{-2*pi}</param>
        <param name="max">{2*pi}</param>
      </command_interface>
      <state_interface name="position">
        <!-- initial position for the FakeSystem and simulation -->
        <param name="initial_value">-1.571</param>
      </state_interface>
      <state_interface name="velocity"/>
      <state_interface name="effort"/>
    </joint>
    <joint name="wrist_3_joint">
      <command_interface name="position">
        <param name="min">{-2*pi}</param>
        <param name="max">{2*pi}</param>
      </command_interface>
      <state_interface name="position">
        <!-- initial position for the FakeSystem and simulation -->
        <param name="initial_value">0.0</param>
      </state_interface>
      <state_interface name="velocity"/>
      <state_interface name="effort"/>
    </joint>
  </ros2_control>
  <link name="fanuc_base_link">
    <visual>
      <origin rpy="0 0 0" xyz="0 0 0"/>
      <geometry>
        <mesh filename="file:///home/ubuntu/aprs_ws/install/aprs_description/share/aprs_description/meshes/fanuc/visual/base_link.stl"/>
      </geometry>
      <material name="">
        <color rgba="0.278431372549 0.278431372549 0.278431372549 1.0"/>
      </material>
    </visual>
    <collision>
      <origin rpy="0 0 0" xyz="0 0 0"/>
      <geometry>
        <mesh filename="file:///home/ubuntu/aprs_ws/install/aprs_description/share/aprs_description/meshes/fanuc/collision/base_link.stl"/>
      </geometry>
    </collision>
    <inertial>
      <mass value="0.1"/>
      <inertia ixx="0.03" ixy="0.0" ixz="0.0" iyy="0.03" iyz="0.0" izz="0.03"/>
    </inertial>
  </link>
  <link name="link_1">
    <visual>
      <origin rpy="0 0 0" xyz="0 0 0"/>
      <geometry>
        <mesh filename="file:///home/ubuntu/aprs_ws/install/aprs_description/share/aprs_description/meshes/fanuc/visual/link_1.stl"/>
      </geometry>
      <material name="">
        <color rgba="0.96 0.76 0.13 1.0"/>
      </material>
    </visual>
    <collision>
      <origin rpy="0 0 0" xyz="0 0 0"/>
      <geometry>
        <mesh filename="file:///home/ubuntu/aprs_ws/install/aprs_description/share/aprs_description/meshes/fanuc/collision/link_1.stl"/>
      </geometry>
    </collision>
    <inertial>
      <origin rpy="0 0 0" xyz="0 0 0"/>
      <mass value="1"/>
      <inertia ixx="0.0226667" ixy="0.0" ixz="0.0" iyy="0.0226667" iyz="0.0" izz="0.0226667"/>
    </inertial>
  </link>
  <link name="link_2">
    <visual>
      <origin rpy="0 0 0" xyz="0 0 0"/>
      <geometry>
        <mesh filename="file:///home/ubuntu/aprs_ws/install/aprs_description/share/aprs_description/meshes/fanuc/visual/link_2.stl"/>
      </geometry>
      <material name="">
        <color rgba="0.96 0.76 0.13 1.0"/>
      </material>
    </visual>
    <collision>
      <origin rpy="0 0 0" xyz="0 0 0"/>
      <geometry>
        <mesh filename="file:///home/ubuntu/aprs_ws/install/aprs_description/share/aprs_description/meshes/fanuc/collision/link_2.stl"/>
      </geometry>
    </collision>
    <inertial>
      <origin rpy="0 0 0" xyz="0 0 0"/>
      <mass value="1"/>
      <inertia ixx="0.0226667" ixy="0.0" ixz="0.0" iyy="0.0226667" iyz="0.0" izz="0.0226667"/>
    </inertial>
  </link>
  <link name="link_3">
    <visual>
      <origin rpy="0 0 0" xyz="0 0 0"/>
      <geometry>
        <mesh filename="file:///home/ubuntu/aprs_ws/install/aprs_description/share/aprs_description/meshes/fanuc/visual/link_3.stl"/>
      </geometry>
      <material name="">
        <color rgba="0.96 0.76 0.13 1.0"/>
      </material>
    </visual>
    <collision>
      <origin rpy="0 0 0" xyz="0 0 0"/>
      <geometry>
        <mesh filename="file:///home/ubuntu/aprs_ws/install/aprs_description/share/aprs_description/meshes/fanuc/collision/link_3.stl"/>
      </geometry>
    </collision>
    <inertial>
      <origin rpy="0 0 0" xyz="0 0 0"/>
      <mass value="1"/>
      <inertia ixx="0.0226667" ixy="0.0" ixz="0.0" iyy="0.0226667" iyz="0.0" izz="0.0226667"/>
    </inertial>
  </link>
  <link name="link_4">
    <visual>
      <origin rpy="0 0 0" xyz="0 0 0"/>
      <geometry>
        <mesh filename="file:///home/ubuntu/aprs_ws/install/aprs_description/share/aprs_description/meshes/fanuc/visual/link_4.stl"/>
      </geometry>
      <material name="">
        <color rgba="0.96 0.76 0.13 1.0"/>
      </material>
    </visual>
    <collision>
      <origin rpy="0 0 0" xyz="0 0 0"/>
      <geometry>
        <mesh filename="file:///home/ubuntu/aprs_ws/install/aprs_description/share/aprs_description/meshes/fanuc/collision/link_4.stl"/>
      </geometry>
    </collision>
    <inertial>
      <origin rpy="0 0 0" xyz="0 0 0"/>
      <mass value="1"/>
      <inertia ixx="0.0226667" ixy="0.0" ixz="0.0" iyy="0.0226667" iyz="0.0" izz="0.0226667"/>
    </inertial>
  </link>
  <link name="link_5">
    <visual>
      <origin rpy="0 0 0" xyz="0 0 0"/>
      <geometry>
        <mesh filename="file:///home/ubuntu/aprs_ws/install/aprs_description/share/aprs_description/meshes/fanuc/visual/link_5.stl"/>
      </geometry>
      <material name="">
        <color rgba="0.96 0.76 0.13 1.0"/>
      </material>
    </visual>
    <collision>
      <origin rpy="0 0 0" xyz="0 0 0"/>
      <geometry>
        <mesh filename="file:///home/ubuntu/aprs_ws/install/aprs_description/share/aprs_description/meshes/fanuc/collision/link_5.stl"/>
      </geometry>
    </collision>
    <inertial>
      <origin rpy="0 0 0" xyz="0 0 0"/>
      <mass value="1"/>
      <inertia ixx="0.0226667" ixy="0.0" ixz="0.0" iyy="0.0226667" iyz="0.0" izz="0.0226667"/>
    </inertial>
  </link>
  <link name="link_6">
    <visual>
      <origin rpy="0 0 0" xyz="0 0 0"/>
      <geometry>
        <mesh filename="file:///home/ubuntu/aprs_ws/install/aprs_description/share/aprs_description/meshes/fanuc/visual/link_6.stl"/>
      </geometry>
      <material name="">
        <color rgba="0.15 0.15 0.15 1.0"/>
      </material>
    </visual>
    <collision>
      <origin rpy="0 0 0" xyz="0 0 0"/>
      <geometry>
        <mesh filename="file:///home/ubuntu/aprs_ws/install/aprs_description/share/aprs_description/meshes/fanuc/collision/link_6.stl"/>
      </geometry>
    </collision>
    <inertial>
      <origin rpy="0 0 0" xyz="0 0 0"/>
      <mass value="1"/>
      <inertia ixx="0.0226667" ixy="0.0" ixz="0.0" iyy="0.0226667" iyz="0.0" izz="0.0226667"/>
    </inertial>
  </link>
  <!--   <link name="tool0" /> -->
  <joint name="base_joint_" type="fixed">
    <origin rpy="0 0 0" xyz="0 0 0"/>
    <parent link="aprs_fanuc_base_link"/>
    <child link="fanuc_base_link"/>
  </joint>
  <joint name="joint_1" type="revolute">
    <origin rpy="0 0 0" xyz="0 0 0.330"/>
    <parent link="fanuc_base_link"/>
    <child link="link_1"/>
    <axis xyz="0 0 1"/>
    <limit effort="-1" lower="-6.283185307179586" upper="6.283185307179586" velocity="7.85"/>
  </joint>
  <joint name="joint_2" type="revolute">
    <origin rpy="0 0 0" xyz="0.050 0 0"/>
    <parent link="link_1"/>
    <child link="link_2"/>
    <axis xyz="0 1 0"/>
    <limit effort="-1" lower="-6.283185307179586" upper="6.283185307179586" velocity="6.63"/>
  </joint>
  <joint name="joint_3" type="revolute">
    <origin rpy="0 0 0" xyz="0 0 0.330"/>
    <parent link="link_2"/>
    <child link="link_3"/>
    <axis xyz="0 -1 0"/>
    <limit effort="-1" lower="-6.283185307179586" upper="6.283185307179586" velocity="9.08"/>
  </joint>
  <joint name="joint_4" type="revolute">
    <origin rpy="0 0 0" xyz="0 0 0.035"/>
    <parent link="link_3"/>
    <child link="link_4"/>
    <axis xyz="-1 0 0"/>
    <limit effort="-1" lower="-6.283185307179586" upper="6.283185307179586" velocity="9.6"/>
  </joint>
  <joint name="joint_5" type="revolute">
    <origin rpy="0 0 0" xyz="0.335 0 0"/>
    <parent link="link_4"/>
    <child link="link_5"/>
    <axis xyz="0 -1 0"/>
    <limit effort="-1" lower="-6.283185307179586" upper="6.283185307179586" velocity="9.51"/>
  </joint>
  <joint name="joint_6" type="revolute">
    <origin rpy="0 0 0" xyz="0.080 0 0"/>
    <parent link="link_5"/>
    <child link="link_6"/>
    <axis xyz="-1 0 0"/>
    <limit effort="-1" lower="-6.283185307179586" upper="6.283185307179586" velocity="17.45"/>
  </joint>
  <gazebo reference="fanuc_base_link">
    <material>Gazebo/Grey</material>
    <turnGravityOff>true</turnGravityOff>
  </gazebo>
  <gazebo reference="link_1">
    <material>Gazebo/Yellow</material>
    <turnGravityOff>true</turnGravityOff>
  </gazebo>
  <gazebo reference="link_2">
    <material>Gazebo/Yellow</material>
    <turnGravityOff>true</turnGravityOff>
  </gazebo>
  <gazebo reference="link_3">
    <material>Gazebo/Yellow</material>
    <turnGravityOff>true</turnGravityOff>
  </gazebo>
  <gazebo reference="link_4">
    <material>Gazebo/Yellow</material>
    <turnGravityOff>true</turnGravityOff>
  </gazebo>
  <gazebo reference="link_5">
    <material>Gazebo/Yellow</material>
    <turnGravityOff>true</turnGravityOff>
  </gazebo>
  <gazebo reference="link_6">
    <material>Gazebo/Yellow</material>
    <turnGravityOff>true</turnGravityOff>
  </gazebo>
  <ros2_control name="fanuc" type="system">
    <hardware>
      <plugin>gz_ros2_control/GazeboSimSystem</plugin>
    </hardware>
    <joint name="joint_1">
      <command_interface name="position">
        <param name="min">{-2*pi}</param>
        <param name="max">{2*pi}</param>
      </command_interface>
      <state_interface name="position">
        <param name="initial_value">0.0</param>
      </state_interface>
      <state_interface name="velocity"/>
      <state_interface name="effort"/>
    </joint>
    <joint name="joint_2">
      <command_interface name="position">
        <param name="min">{-2*pi}</param>
        <param name="max">{2*pi}</param>
      </command_interface>
      <state_interface name="position">
        <param name="initial_value">-1.57</param>
      </state_interface>
      <state_interface name="velocity"/>
      <state_interface name="effort"/>
    </joint>
    <joint name="joint_3">
      <command_interface name="position">
        <param name="min">{-pi}</param>
        <param name="max">{pi}</param>
      </command_interface>
      <state_interface name="position">
        <param name="initial_value">0.0</param>
      </state_interface>
      <state_interface name="velocity"/>
      <state_interface name="effort"/>
    </joint>
    <joint name="joint_4">
      <command_interface name="position">
        <param name="min">{-2*pi}</param>
        <param name="max">{2*pi}</param>
      </command_interface>
      <state_interface name="position">
        <param name="initial_value">-1.57</param>
      </state_interface>
      <state_interface name="velocity"/>
      <state_interface name="effort"/>
    </joint>
    <joint name="joint_5">
      <command_interface name="position">
        <param name="min">{-2*pi}</param>
        <param name="max">{2*pi}</param>
      </command_interface>
      <state_interface name="position">
        <param name="initial_value">0.0</param>
      </state_interface>
      <state_interface name="velocity"/>
      <state_interface name="effort"/>
    </joint>
    <joint name="joint_6">
      <command_interface name="position">
        <param name="min">{-2*pi}</param>
        <param name="max">{2*pi}</param>
      </command_interface>
      <state_interface name="position">
        <param name="initial_value">0.0</param>
      </state_interface>
      <state_interface name="velocity"/>
      <state_interface name="effort"/>
    </joint>
  </ros2_control>
  <!-- Inclue franka robot macro -->
  <!-- <xacro:include filename="$(find franka_description)/robots/common/franka_robot.xacro"/> -->
  <!-- safety_distance: Minimum safety distance in [m] by which the collision volumes are expanded and which is enforced during robot motions -->
  <!-- arm_id: Namespace of the robot arm. Serves to differentiate between arms in case of multiple instances. -->
  <!-- joint_limits: description of the joint limits that comes from a YAML file. Example definition: ${xacro.load_yaml('$(find franka_description)/robots/fr3/joint_limits.yaml')} -->
  <!-- kinematics: description of the kinematics that comes from a YAML file. Example definition: ${xacro.load_yaml('$(find franka_description)/robots/fr3/kinematics.yaml')} -->
  <!-- inertials: description of the inertials that comes from a YAML file. Example definition: ${xacro.load_yaml('$(find franka_description)/robots/fr3/inertials.yaml')} -->
  <!-- dynamics: description of the dynamics that comes from a YAML file. Example definition: ${xacro.load_yaml('$(find franka_description)/robots/fr3/dynamics.yaml')} -->
  <link name="aprs_franka_base_link"> 
      </link>
  <joint name="aprs_franka_base_link_joint" type="fixed">
    <parent link="aprs_franka_base_link"/>
    <child link="fr3_link0"/>
    <origin rpy="0 0 0" xyz="0 0 0"/>
  </joint>
  <!-- sub-link defining detailed meshes for collision with environment -->
  <link name="fr3_link0">
    <visual name="fr3_link0_visual">
      <geometry>
        <mesh filename="/home/ubuntu/aprs_ws/install/aprs_description/share/aprs_description/meshes/fr3/visual/link0.dae"/>
      </geometry>
    </visual>
    <collision name="fr3_link0_collision">
      <geometry>
        <mesh filename="/home/ubuntu/aprs_ws/install/aprs_description/share/aprs_description/meshes/fr3/collision/link0.stl"/>
      </geometry>
    </collision>
    <inertial>
      <origin rpy="0 0 0" xyz="-0.041018 -0.00014 0.049974"/>
      <mass value="0.629769"/>
      <inertia ixx="0.00315" ixy="8.2904e-07" ixz="0.00015" iyy="0.00388" iyz="8.2299e-06" izz="0.004285"/>
    </inertial>
  </link>
  <!-- sub-link defining detailed meshes for collision with environment -->
  <link name="fr3_link1">
    <visual name="fr3_link1_visual">
      <geometry>
        <mesh filename="/home/ubuntu/aprs_ws/install/aprs_description/share/aprs_description/meshes/fr3/visual/link1.dae"/>
      </geometry>
    </visual>
    <collision name="fr3_link1_collision">
      <geometry>
        <mesh filename="/home/ubuntu/aprs_ws/install/aprs_description/share/aprs_description/meshes/fr3/collision/link1.stl"/>
      </geometry>
    </collision>
    <inertial>
      <origin rpy="0 0 0" xyz="0.003875 0.002081 -0.04762"/>
      <mass value="4.970684"/>
      <inertia ixx="0.70337" ixy="-0.000139" ixz="0.006772" iyy="0.70661" iyz="0.019169" izz="0.009117"/>
    </inertial>
  </link>
  <joint name="fr3_joint1" type="revolute">
    <origin rpy="0 0 0" xyz="0 0 0.333"/>
    <parent link="fr3_link0"/>
    <child link="fr3_link1"/>
    <axis xyz="0 0 1"/>
    <limit effort="87.0" lower="-2.7437" upper="2.7437" velocity="2.62"/>
    <safety_controller k_position="100.0" k_velocity="40.0" soft_lower_limit="-2.7437" soft_upper_limit="2.7437"/>
    <dynamics D="1" K="7000" damping="0.003" friction="0.0" mu_coulomb="0" mu_viscous="16"/>
  </joint>
  <!-- sub-link defining detailed meshes for collision with environment -->
  <link name="fr3_link2">
    <visual name="fr3_link2_visual">
      <geometry>
        <mesh filename="/home/ubuntu/aprs_ws/install/aprs_description/share/aprs_description/meshes/fr3/visual/link2.dae"/>
      </geometry>
    </visual>
    <collision name="fr3_link2_collision">
      <geometry>
        <mesh filename="/home/ubuntu/aprs_ws/install/aprs_description/share/aprs_description/meshes/fr3/collision/link2.stl"/>
      </geometry>
    </collision>
    <inertial>
      <origin rpy="0 0 0" xyz="-0.003141 -0.02872  0.003495"/>
      <mass value="0.646926"/>
      <inertia ixx="0.007962" ixy="-0.003925" ixz="0.010254" iyy="0.02811" iyz="0.000704" izz="0.025995"/>
    </inertial>
  </link>
  <joint name="fr3_joint2" type="revolute">
    <origin rpy="-1.570796326794897 0 0" xyz="0 0 0"/>
    <parent link="fr3_link1"/>
    <child link="fr3_link2"/>
    <axis xyz="0 0 1"/>
    <limit effort="87.0" lower="-1.7837" upper="1.7837" velocity="2.62"/>
    <safety_controller k_position="100.0" k_velocity="40.0" soft_lower_limit="-1.7837" soft_upper_limit="1.7837"/>
    <dynamics D="1" K="7000" damping="0.003" friction="0.0" mu_coulomb="0" mu_viscous="16"/>
  </joint>
  <!-- sub-link defining detailed meshes for collision with environment -->
  <link name="fr3_link3">
    <visual name="fr3_link3_visual">
      <geometry>
        <mesh filename="/home/ubuntu/aprs_ws/install/aprs_description/share/aprs_description/meshes/fr3/visual/link3.dae"/>
      </geometry>
    </visual>
    <collision name="fr3_link3_collision">
      <geometry>
        <mesh filename="/home/ubuntu/aprs_ws/install/aprs_description/share/aprs_description/meshes/fr3/collision/link3.stl"/>
      </geometry>
    </collision>
    <inertial>
      <origin rpy="0 0 0" xyz="2.7518e-02 3.9252e-02 -6.6502e-02"/>
      <mass value="3.228604"/>
      <inertia ixx="0.037242" ixy="-0.004761" ixz="-0.011396" iyy="0.036155" iyz="-0.012805" izz="0.01083"/>
    </inertial>
  </link>
  <joint name="fr3_joint3" type="revolute">
    <origin rpy="1.570796326794897 0 0" xyz="0 -0.316 0"/>
    <parent link="fr3_link2"/>
    <child link="fr3_link3"/>
    <axis xyz="0 0 1"/>
    <limit effort="87.0" lower="-2.9007" upper="2.9007" velocity="2.62"/>
    <safety_controller k_position="100.0" k_velocity="40.0" soft_lower_limit="-2.9007" soft_upper_limit="2.9007"/>
    <dynamics D="1" K="7000" damping="0.003" friction="0.0" mu_coulomb="0" mu_viscous="16"/>
  </joint>
  <!-- sub-link defining detailed meshes for collision with environment -->
  <link name="fr3_link4">
    <visual name="fr3_link4_visual">
      <geometry>
        <mesh filename="/home/ubuntu/aprs_ws/install/aprs_description/share/aprs_description/meshes/fr3/visual/link4.dae"/>
      </geometry>
    </visual>
    <collision name="fr3_link4_collision">
      <geometry>
        <mesh filename="/home/ubuntu/aprs_ws/install/aprs_description/share/aprs_description/meshes/fr3/collision/link4.stl"/>
      </geometry>
    </collision>
    <inertial>
      <origin rpy="0 0 0" xyz="-5.317e-02 1.04419e-01 2.7454e-02"/>
      <mass value="3.587895"/>
      <inertia ixx="0.025853" ixy="0.007796" ixz="-0.001332" iyy="0.019552" iyz="0.008641" izz="0.028323"/>
    </inertial>
  </link>
  <joint name="fr3_joint4" type="revolute">
    <origin rpy="1.570796326794897 0 0" xyz="0.0825 0 0"/>
    <parent link="fr3_link3"/>
    <child link="fr3_link4"/>
    <axis xyz="0 0 1"/>
    <limit effort="87.0" lower="-3.0421" upper="-0.1518" velocity="2.62"/>
    <safety_controller k_position="100.0" k_velocity="40.0" soft_lower_limit="-3.0421" soft_upper_limit="-0.1518"/>
    <dynamics D="1" K="7000" damping="0.003" friction="0.0" mu_coulomb="0" mu_viscous="16"/>
  </joint>
  <!-- sub-link defining detailed meshes for collision with environment -->
  <link name="fr3_link5">
    <visual name="fr3_link5_visual">
      <geometry>
        <mesh filename="/home/ubuntu/aprs_ws/install/aprs_description/share/aprs_description/meshes/fr3/visual/link5.dae"/>
      </geometry>
    </visual>
    <collision name="fr3_link5_collision">
      <geometry>
        <mesh filename="/home/ubuntu/aprs_ws/install/aprs_description/share/aprs_description/meshes/fr3/collision/link5.stl"/>
      </geometry>
    </collision>
    <inertial>
      <origin rpy="0 0 0" xyz="-1.1953e-02 4.1065e-02 -3.8437e-02"/>
      <mass value="1.225946"/>
      <inertia ixx="0.035549" ixy="-0.002117" ixz="-0.004037" iyy="0.029474" iyz="0.000229" izz="0.008627"/>
    </inertial>
  </link>
  <joint name="fr3_joint5" type="revolute">
    <origin rpy="-1.570796326794897 0 0" xyz="-0.0825 0.384 0"/>
    <parent link="fr3_link4"/>
    <child link="fr3_link5"/>
    <axis xyz="0 0 1"/>
    <limit effort="12.0" lower="-2.8065" upper="2.8065" velocity="5.26"/>
    <safety_controller k_position="100.0" k_velocity="40.0" soft_lower_limit="-2.8065" soft_upper_limit="2.8065"/>
    <dynamics D="1" K="7000" damping="0.003" friction="0.0" mu_coulomb="0" mu_viscous="16"/>
  </joint>
  <!-- sub-link defining detailed meshes for collision with environment -->
  <link name="fr3_link6">
    <visual name="fr3_link6_visual">
      <geometry>
        <mesh filename="/home/ubuntu/aprs_ws/install/aprs_description/share/aprs_description/meshes/fr3/visual/link6.dae"/>
      </geometry>
    </visual>
    <collision name="fr3_link6_collision">
      <geometry>
        <mesh filename="/home/ubuntu/aprs_ws/install/aprs_description/share/aprs_description/meshes/fr3/collision/link6.stl"/>
      </geometry>
    </collision>
    <inertial>
      <origin rpy="0 0 0" xyz="6.0149e-02 -1.4117e-02 -1.0517e-02"/>
      <mass value="1.666555"/>
      <inertia ixx="0.001964" ixy="0.000109" ixz="-0.001158" iyy="0.004354" iyz="0.000341" izz="0.005433"/>
    </inertial>
  </link>
  <joint name="fr3_joint6" type="revolute">
    <origin rpy="1.570796326794897 0 0" xyz="0 0 0"/>
    <parent link="fr3_link5"/>
    <child link="fr3_link6"/>
    <axis xyz="0 0 1"/>
    <limit effort="12.0" lower="0.5445" upper="4.5169" velocity="4.18"/>
    <safety_controller k_position="100.0" k_velocity="40.0" soft_lower_limit="0.5445" soft_upper_limit="4.5169"/>
    <dynamics D="1" K="7000" damping="0.003" friction="0.0" mu_coulomb="0" mu_viscous="16"/>
  </joint>
  <!-- sub-link defining detailed meshes for collision with environment -->
  <link name="fr3_link7">
    <visual name="fr3_link7_visual">
      <geometry>
        <mesh filename="/home/ubuntu/aprs_ws/install/aprs_description/share/aprs_description/meshes/fr3/visual/link7.dae"/>
      </geometry>
    </visual>
    <collision name="fr3_link7_collision">
      <geometry>
        <mesh filename="/home/ubuntu/aprs_ws/install/aprs_description/share/aprs_description/meshes/fr3/collision/link7.stl"/>
      </geometry>
    </collision>
    <inertial>
      <origin rpy="0 0 0" xyz="1.0517e-02 -4.252e-03 6.1597e-02"/>
      <mass value="0.735522"/>
      <inertia ixx="0.012516" ixy="-0.000428" ixz="-0.001196" iyy="0.010027" iyz="-0.000741" izz="0.004815"/>
    </inertial>
  </link>
  <joint name="fr3_joint7" type="revolute">
    <origin rpy="1.570796326794897 0 0" xyz="0.088 0 0"/>
    <parent link="fr3_link6"/>
    <child link="fr3_link7"/>
    <axis xyz="0 0 1"/>
    <limit effort="12.0" lower="-3.0159" upper="3.0159" velocity="5.26"/>
    <safety_controller k_position="100.0" k_velocity="40.0" soft_lower_limit="-3.0159" soft_upper_limit="3.0159"/>
    <dynamics D="1" K="7000" damping="0.003" friction="0.0" mu_coulomb="0" mu_viscous="16"/>
  </joint>
  <link name="fr3_link8"/>
  <joint name="fr3_joint8" type="fixed">
    <origin rpy="0 0 0" xyz="0 0 0.107"/>
    <parent link="fr3_link7"/>
    <child link="fr3_link8"/>
  </joint>
  <joint name="fr3_hand_joint" type="fixed">
    <parent link="fr3_link8"/>
    <child link="fr3_hand"/>
    <origin rpy="0 0 0" xyz="0 0 0"/>
  </joint>
  <!-- sub-link defining detailed meshes for collision with environment -->
  <link name="fr3_hand">
    <visual name="fr3_hand_visual">
      <geometry>
        <mesh filename="/home/ubuntu/aprs_ws/install/aprs_description/share/aprs_description/meshes/fr3/visual/hand.dae"/>
      </geometry>
    </visual>
    <collision name="fr3_hand_collision">
      <geometry>
        <mesh filename="/home/ubuntu/aprs_ws/install/aprs_description/share/aprs_description/meshes/fr3/collision/hand.stl"/>
      </geometry>
    </collision>
    <inertial>
      <origin rpy="0 0 0" xyz="-0.01 0 0.03"/>
      <mass value="0.73"/>
      <inertia ixx="0.001" ixy="0" ixz="0" iyy="0.0025" iyz="0" izz="0.0017"/>
    </inertial>
  </link>
  <!-- Define the hand_tcp frame -->
  <link name="fr3_hand_tcp"/>
  <joint name="fr3_hand_tcp_joint" type="fixed">
    <origin rpy="0 0 0" xyz="0 0 0.1034"/>
    <parent link="fr3_hand"/>
    <child link="fr3_hand_tcp"/>
  </joint>
  <link name="fr3_leftfinger">
    <visual>
      <geometry>
        <mesh filename="/home/ubuntu/aprs_ws/install/aprs_description/share/aprs_description/meshes/fr3/visual/finger.dae"/>
      </geometry>
    </visual>
    <!-- screw mount -->
    <collision>
      <origin rpy="0 0 0" xyz="0 18.5e-3 11e-3"/>
      <geometry>
        <box size="22e-3 15e-3 20e-3"/>
      </geometry>
    </collision>
    <!-- cartriage sledge -->
    <collision>
      <origin rpy="0 0 0" xyz="0 6.8e-3 2.2e-3"/>
      <geometry>
        <box size="22e-3 8.8e-3 3.8e-3"/>
      </geometry>
    </collision>
    <!-- diagonal finger -->
    <collision>
      <origin rpy="0.5235987755982988 0 0" xyz="0 15.9e-3 28.35e-3"/>
      <geometry>
        <box size="17.5e-3 7e-3 23.5e-3"/>
      </geometry>
    </collision>
    <!-- rubber tip with which to grasp -->
    <collision>
      <origin rpy="0 0 0" xyz="0 7.58e-3 45.25e-3"/>
      <geometry>
        <box size="17.5e-3 15.2e-3 18.5e-3"/>
      </geometry>
    </collision>
  </link>
  <link name="fr3_rightfinger">
    <visual>
      <origin rpy="0 0 3.141592653589793" xyz="0 0 0"/>
      <geometry>
        <mesh filename="/home/ubuntu/aprs_ws/install/aprs_description/share/aprs_description/meshes/fr3/visual/finger.dae"/>
      </geometry>
    </visual>
    <!-- screw mount -->
    <collision>
      <origin rpy="0 0 0" xyz="0 -18.5e-3 11e-3"/>
      <geometry>
        <box size="22e-3 15e-3 20e-3"/>
      </geometry>
    </collision>
    <!-- cartriage sledge -->
    <collision>
      <origin rpy="0 0 0" xyz="0 -6.8e-3 2.2e-3"/>
      <geometry>
        <box size="22e-3 8.8e-3 3.8e-3"/>
      </geometry>
    </collision>
    <!-- diagonal finger -->
    <collision>
      <origin rpy="-0.5235987755982988 0 0" xyz="0 -15.9e-3 28.35e-3"/>
      <geometry>
        <box size="17.5e-3 7e-3 23.5e-3"/>
      </geometry>
    </collision>
    <!-- rubber tip with which to grasp -->
    <collision>
      <origin rpy="0 0 0" xyz="0 -7.58e-3 45.25e-3"/>
      <geometry>
        <box size="17.5e-3 15.2e-3 18.5e-3"/>
      </geometry>
    </collision>
  </link>
  <joint name="fr3_finger_joint1" type="prismatic">
    <parent link="fr3_hand"/>
    <child link="fr3_leftfinger"/>
    <origin rpy="0 0 0" xyz="0 0 0.0584"/>
    <axis xyz="0 1 0"/>
    <limit effort="100" lower="0.0" upper="0.04" velocity="0.2"/>
    <dynamics damping="0.3"/>
  </joint>
  <joint name="fr3_finger_joint2" type="prismatic">
    <parent link="fr3_hand"/>
    <child link="fr3_rightfinger"/>
    <origin rpy="0 0 0" xyz="0 0 0.0584"/>
    <axis xyz="0 -1 0"/>
    <limit effort="100" lower="0.0" upper="0.04" velocity="0.2"/>
    <mimic joint="fr3_finger_joint1"/>
    <dynamics damping="0.3"/>
  </joint>
  <!-- Run fanuc macro -->
  <ros2_control name="franka" type="system">
    <hardware>
      <plugin>gz_ros2_control/GazeboSimSystem</plugin>
    </hardware>
    <joint name="fr3_joint1">
      <command_interface name="position">
        <param name="min">-2.7437</param>
        <param name="max">2.7437</param>
      </command_interface>
      <state_interface name="position">
        <param name="initial_value">0.0</param>
      </state_interface>
      <state_interface name="velocity"/>
      <state_interface name="effort"/>
    </joint>
    <joint name="fr3_joint2">
      <command_interface name="position">
        <param name="min">-1.7837</param>
        <param name="max">1.7837</param>
      </command_interface>
      <state_interface name="position">
        <param name="initial_value">0.0</param>
      </state_interface>
      <state_interface name="velocity"/>
      <state_interface name="effort"/>
    </joint>
    <joint name="fr3_joint3">
      <command_interface name="position">
        <param name="min">-2.9007</param>
        <param name="max">2.9007</param>
      </command_interface>
      <state_interface name="position">
        <param name="initial_value">0.0</param>
      </state_interface>
      <state_interface name="velocity"/>
      <state_interface name="effort"/>
    </joint>
    <joint name="fr3_joint4">
      <command_interface name="position">
        <param name="min">-3.0421</param>
        <param name="max">-0.1518</param>
      </command_interface>
      <state_interface name="position">
        <param name="initial_value">-1.57</param>
      </state_interface>
      <state_interface name="velocity"/>
      <state_interface name="effort"/>
    </joint>
    <joint name="fr3_joint5">
      <command_interface name="position">
        <param name="min">-2.8065</param>
        <param name="max">2.8065</param>
      </command_interface>
      <state_interface name="position">
        <param name="initial_value">0.0</param>
      </state_interface>
      <state_interface name="velocity"/>
      <state_interface name="effort"/>
    </joint>
    <joint name="fr3_joint6">
      <command_interface name="position">
        <param name="min">0.5445</param>
        <param name="max">4.5169</param>
      </command_interface>
      <state_interface name="position">
        <param name="initial_value">1.57</param>
      </state_interface>
      <state_interface name="velocity"/>
      <state_interface name="effort"/>
    </joint>
    <joint name="fr3_joint7">
      <command_interface name="position">
        <param name="min">-3.0159</param>
        <param name="max">3.0159</param>
      </command_interface>
      <state_interface name="position">
        <param name="initial_value">0.0</param>
      </state_interface>
      <state_interface name="velocity"/>
      <state_interface name="effort"/>
    </joint>
  </ros2_control>
  <!-- color of robot. important-->
  <material name="white">
    <color rgba="1 1 1 1"/>
  </material>
  <!-- motoman_base_link-->
  <link name="motoman_base_link">
    <inertial>
      <mass value="1.0"/>
      <!--xacro:inertia_origin_base_link/-->
      <inertia ixx="0.0226667" ixy="0.0" ixz="0.0" iyy="0.0226667" iyz="0.0" izz="0.0226667"/>
    </inertial>
    <visual>
      <origin rpy="0 0 0" xyz="0 0 0"/>
      <geometry>
        <mesh filename="file:///home/ubuntu/aprs_ws/install/aprs_description/share/aprs_description/meshes/motoman/motoman_base_link.STL"/>
      </geometry>
      <material name="white"/>
    </visual>
    <collision>
      <origin rpy="0 0 0" xyz="0 0 0"/>
      <geometry>
        <mesh filename="file:///home/ubuntu/aprs_ws/install/aprs_description/share/aprs_description/meshes/motoman/motoman_base_link.STL"/>
      </geometry>
    </collision>
  </link>
  <!-- link_s-->
  <link name="link_s">
    <inertial>
      <mass value="1.0"/>
      <inertia ixx="0.0226667" ixy="0.0" ixz="0.0" iyy="0.0226667" iyz="0.0" izz="0.0226667"/>
    </inertial>
    <visual>
      <origin rpy="0 0 0" xyz="0 0 0"/>
      <geometry>
        <mesh filename="file:///home/ubuntu/aprs_ws/install/aprs_description/share/aprs_description/meshes/motoman/link_s.STL"/>
      </geometry>
      <material name="white"/>
    </visual>
    <collision>
      <origin rpy="0 0 0" xyz="0 0 0"/>
      <geometry>
        <mesh filename="file:///home/ubuntu/aprs_ws/install/aprs_description/share/aprs_description/meshes/motoman/link_s.STL"/>
      </geometry>
    </collision>
  </link>
  <joint name="motoman_base_joint" type="fixed">
    <origin rpy="0 0 0" xyz="0 0 0"/>
    <parent link="aprs_motoman_base_link"/>
    <child link="motoman_base_link"/>
  </joint>
  <joint name="joint_s" type="revolute">
    <origin rpy="1.5708 0 0" xyz="0 0 0.112"/>
    <parent link="motoman_base_link"/>
    <child link="link_s"/>
    <axis xyz="0 1 0"/>
    <limit effort="1000" lower="-3.1415" upper="3.1415" velocity="2.2698"/>
    <calibration falling="0" rising="0"/>
    <dynamics damping="0" fraction="0"/>
    <safety_controller k_position="0" k_velocity="0" soft_lower="0" soft_upper="0"/>
  </joint>
  <!-- link_l-->
  <link name="link_l">
    <inertial>
      <mass value="1.0"/>
      <inertia ixx="0.0226667" ixy="0.0" ixz="0.0" iyy="0.0226667" iyz="0.0" izz="0.0226667"/>
    </inertial>
    <visual>
      <origin rpy="0 0 0" xyz="0 0 0"/>
      <geometry>
        <mesh filename="file:///home/ubuntu/aprs_ws/install/aprs_description/share/aprs_description/meshes/motoman/link_l.STL"/>
      </geometry>
      <material name="white"/>
    </visual>
    <collision>
      <origin rpy="0 0 0" xyz="0 0 0"/>
      <geometry>
        <mesh filename="file:///home/ubuntu/aprs_ws/install/aprs_description/share/aprs_description/meshes/motoman/link_l.STL"/>
      </geometry>
    </collision>
  </link>
  <!-- joint_l (link_s | joint_l) -->
  <joint name="joint_l" type="revolute">
    <origin rpy="0 0 0" xyz="0 0.298 0"/>
    <parent link="link_s"/>
    <child link="link_l"/>
    <axis xyz="0 0 1"/>
    <limit effort="1000" lower="-1.9198" upper="1.9198" velocity="2.2698"/>
    <calibration falling="0" rising="0"/>
    <dynamics damping="0" fraction="0"/>
    <safety_controller k_position="0" k_velocity="0" soft_lower="0" soft_upper="0"/>
  </joint>
  <!-- link_e-->
  <link name="link_e">
    <inertial>
      <mass value="1.0"/>
      <inertia ixx="0.0226667" ixy="0.0" ixz="0.0" iyy="0.0226667" iyz="0.0" izz="0.0226667"/>
    </inertial>
    <visual>
      <origin rpy="0 0 0" xyz="0 0 0"/>
      <geometry>
        <mesh filename="file:///home/ubuntu/aprs_ws/install/aprs_description/share/aprs_description/meshes/motoman/link_e.STL"/>
      </geometry>
      <material name="white"/>
    </visual>
    <collision>
      <origin rpy="0 0 0" xyz="0 0 0"/>
      <geometry>
        <mesh filename="file:///home/ubuntu/aprs_ws/install/aprs_description/share/aprs_description/meshes/motoman/link_e.STL"/>
      </geometry>
    </collision>
  </link>
  <!-- joint_e (link_l | joint_e) -->
  <joint name="joint_e" type="revolute">
    <origin rpy="0 0 0" xyz="0 0.247135547651375 0"/>
    <parent link="link_l"/>
    <child link="link_e"/>
    <axis xyz="0 1 0"/>
    <limit effort="1000" lower="-2.967" upper="2.967" velocity="2.2698"/>
    <calibration falling="0" rising="0"/>
    <dynamics damping="0" fraction="0"/>
    <safety_controller k_position="0" k_velocity="0" soft_lower="0" soft_upper="0"/>
  </joint>
  <!-- link_u-->
  <link name="link_u">
    <inertial>
      <mass value="1.0"/>
      <inertia ixx="0.0226667" ixy="0.0" ixz="0.0" iyy="0.0226667" iyz="0.0" izz="0.0226667"/>
    </inertial>
    <visual>
      <origin rpy="0 0 0" xyz="0 0 0"/>
      <geometry>
        <mesh filename="file:///home/ubuntu/aprs_ws/install/aprs_description/share/aprs_description/meshes/motoman/link_u.STL"/>
      </geometry>
      <material name="white"/>
    </visual>
    <collision>
      <origin rpy="0 0 0" xyz="0 0 0"/>
      <geometry>
        <mesh filename="file:///home/ubuntu/aprs_ws/install/aprs_description/share/aprs_description/meshes/motoman/link_u.STL"/>
      </geometry>
    </collision>
  </link>
  <!-- joint_u (link_e | joint_u) -->
  <joint name="joint_u" type="revolute">
    <origin rpy="0 0 0" xyz="0 0.242864452348634 0"/>
    <parent link="link_e"/>
    <child link="link_u"/>
    <axis xyz="0 0 1"/>
    <limit effort="1000" lower="-2.967" upper="2.967" velocity="2.2698"/>
    <calibration falling="0" rising="0"/>
    <dynamics damping="0" fraction="0"/>
    <safety_controller k_position="0" k_velocity="0" soft_lower="0" soft_upper="0"/>
  </joint>
  <!-- link_r-->
  <link name="link_r">
    <inertial>
      <mass value="1.0"/>
      <inertia ixx="0.0226667" ixy="0.0" ixz="0.0" iyy="0.0226667" iyz="0.0" izz="0.0226667"/>
    </inertial>
    <visual>
      <origin rpy="0 0 0" xyz="0 0 0"/>
      <geometry>
        <mesh filename="file:///home/ubuntu/aprs_ws/install/aprs_description/share/aprs_description/meshes/motoman/link_r.STL"/>
      </geometry>
      <material name="white"/>
    </visual>
    <collision>
      <origin rpy="0 0 0" xyz="0 0 0"/>
      <geometry>
        <mesh filename="file:///home/ubuntu/aprs_ws/install/aprs_description/share/aprs_description/meshes/motoman/link_r.STL"/>
      </geometry>
    </collision>
  </link>
  <!-- joint_r (link_u | joint_r) -->
  <joint name="joint_r" type="revolute">
    <origin rpy="0 0 0" xyz="0 0.23899999999989 0"/>
    <parent link="link_u"/>
    <child link="link_r"/>
    <axis xyz="0 1 0"/>
    <limit effort="1000" lower="-3.1415" upper="3.1415" velocity="3.4906"/>
    <calibration falling="0" rising="0"/>
    <dynamics damping="0" fraction="0"/>
    <safety_controller k_position="0" k_velocity="0" soft_lower="0" soft_upper="0"/>
  </joint>
  <!-- link_b-->
  <link name="link_b">
    <inertial>
      <mass value="1.0"/>
      <inertia ixx="0.0226667" ixy="0.0" ixz="0.0" iyy="0.0226667" iyz="0.0" izz="0.0226667"/>
    </inertial>
    <visual>
      <origin rpy="0 0 0" xyz="0 0 0"/>
      <geometry>
        <mesh filename="file:///home/ubuntu/aprs_ws/install/aprs_description/share/aprs_description/meshes/motoman/link_b.STL"/>
      </geometry>
      <material name="white"/>
    </visual>
    <collision>
      <origin rpy="0 0 0" xyz="0 0 0"/>
      <geometry>
        <mesh filename="file:///home/ubuntu/aprs_ws/install/aprs_description/share/aprs_description/meshes/motoman/link_b.STL"/>
      </geometry>
    </collision>
  </link>
  <!-- joint_b (link_r | joint_b) -->
  <joint name="joint_b" type="revolute">
    <origin rpy="0 0 0" xyz="0 0.181 0"/>
    <parent link="link_r"/>
    <child link="link_b"/>
    <axis xyz="0 0 1"/>
    <limit effort="1000" lower="-1.9198" upper="1.9198" velocity="3.4906"/>
    <calibration falling="0" rising="0"/>
    <dynamics damping="0" fraction="0"/>
    <safety_controller k_position="0" k_velocity="0" soft_lower="0" soft_upper="0"/>
  </joint>
  <!-- link_t-->
  <link name="link_t">
    <inertial>
      <mass value="1.0"/>
      <inertia ixx="0.0226667" ixy="0.0" ixz="0.0" iyy="0.0226667" iyz="0.0" izz="0.0226667"/>
    </inertial>
    <visual>
      <origin rpy="0 0 0" xyz="0 0 0"/>
      <geometry>
        <mesh filename="file:///home/ubuntu/aprs_ws/install/aprs_description/share/aprs_description/meshes/motoman/link_t.STL"/>
      </geometry>
      <material name="white"/>
    </visual>
    <collision>
      <origin rpy="0 0 0" xyz="0 0 0"/>
      <geometry>
        <mesh filename="file:///home/ubuntu/aprs_ws/install/aprs_description/share/aprs_description/meshes/motoman/link_t.STL"/>
      </geometry>
    </collision>
  </link>
  <!-- joint_t (link_b | joint_t) -->
  <joint name="joint_t" type="revolute">
    <origin rpy="0 0 0" xyz="0 0.164069662461231 0.0015"/>
    <parent link="link_b"/>
    <child link="link_t"/>
    <axis xyz="0 1 0"/>
    <limit effort="1000" lower="-3.1415" upper="3.1415" velocity="7.0"/>
    <calibration falling="0" rising="0"/>
    <dynamics damping="0" fraction="0"/>
    <safety_controller k_position="0" k_velocity="0" soft_lower="0" soft_upper="0"/>
  </joint>
  <!-- link motoman_tool0-->
  <link name="motoman_tool0"/>
  <!-- joint link_t-motoman_tool0 -->
  <joint name="link_t-motoman_tool0" type="fixed">
    <origin rpy="0 0 -3.1415" xyz="0 0 0"/>
    <parent link="link_t"/>
    <child link="motoman_tool0"/>
  </joint>
  <ros2_control name="motoman" type="system">
    <hardware>
      <plugin>gz_ros2_control/GazeboSimSystem</plugin>
    </hardware>
    <joint name="joint_b">
      <command_interface name="position">
        <param name="min">{-2*pi}</param>
        <param name="max">{2*pi}</param>
      </command_interface>
      <state_interface name="position">
        <param name="initial_value">0.0</param>
      </state_interface>
      <state_interface name="velocity"/>
      <state_interface name="effort"/>
    </joint>
    <joint name="joint_e">
      <command_interface name="position">
        <param name="min">{-2*pi}</param>
        <param name="max">{2*pi}</param>
      </command_interface>
      <state_interface name="position">
        <param name="initial_value">-1.57</param>
      </state_interface>
      <state_interface name="velocity"/>
      <state_interface name="effort"/>
    </joint>
    <joint name="joint_l">
      <command_interface name="position">
        <param name="min">{-pi}</param>
        <param name="max">{pi}</param>
      </command_interface>
      <state_interface name="position">
        <param name="initial_value">0.0</param>
      </state_interface>
      <state_interface name="velocity"/>
      <state_interface name="effort"/>
    </joint>
    <joint name="joint_r">
      <command_interface name="position">
        <param name="min">{-2*pi}</param>
        <param name="max">{2*pi}</param>
      </command_interface>
      <state_interface name="position">
        <param name="initial_value">-1.57</param>
      </state_interface>
      <state_interface name="velocity"/>
      <state_interface name="effort"/>
    </joint>
    <joint name="joint_s">
      <command_interface name="position">
        <param name="min">{-2*pi}</param>
        <param name="max">{2*pi}</param>
      </command_interface>
      <state_interface name="position">
        <param name="initial_value">0.0</param>
      </state_interface>
      <state_interface name="velocity"/>
      <state_interface name="effort"/>
    </joint>
    <joint name="joint_t">
      <command_interface name="position">
        <param name="min">{-2*pi}</param>
        <param name="max">{2*pi}</param>
      </command_interface>
      <state_interface name="position">
        <param name="initial_value">0.0</param>
      </state_interface>
      <state_interface name="velocity"/>
      <state_interface name="effort"/>
    </joint>
    <joint name="joint_u">
      <command_interface name="position">
        <param name="min">{-2*pi}</param>
        <param name="max">{2*pi}</param>
      </command_interface>
      <state_interface name="position">
        <param name="initial_value">0.0</param>
      </state_interface>
      <state_interface name="velocity"/>
      <state_interface name="effort"/>
    </joint>
  </ros2_control>
  <gazebo>
    <plugin filename="libgz_ros2_control-system.so" name="gz_ros2_control::GazeboSimROS2ControlPlugin">
      <ros>
      </ros>
      <parameters>/home/ubuntu/aprs_ws/install/aprs_description/share/aprs_description/config/robot_controllers.yaml</parameters>
    </plugin>
  </gazebo>
</robot>
